/home/ycarmon/users/maorkehati/Optimization-Course-Project/image_classification/src/sgd_lr_decay.py:121: UserWarning: This overload of add_ is deprecated:
	add_(Number alpha, Tensor other)
Consider using one of the following signatures instead:
	add_(Tensor other, *, Number alpha) (Triggered internally at  ../torch/csrc/utils/python_arg_parser.cpp:1050.)
  d_p.add_(weight_decay, p.data)
Traceback (most recent call last):
  File "/home/ycarmon/users/maorkehati/Optimization-Course-Project/image_classification/./src/main.py", line 142, in <module>
    main()
  File "/home/ycarmon/users/maorkehati/Optimization-Course-Project/image_classification/./src/main.py", line 69, in main
    running_stats = train(args, train_loader, test_loader, net,
  File "/home/ycarmon/users/maorkehati/Optimization-Course-Project/image_classification/src/train.py", line 83, in train
    test_loss, test_accuracy = evaluate(test_loader, net,
  File "/home/ycarmon/users/maorkehati/Optimization-Course-Project/image_classification/src/evaluate.py", line 24, in evaluate
    for data in test_loader:
  File "/home/ycarmon/users/maorkehati/anaconda3/envs/optp/lib/python3.9/site-packages/torch/utils/data/dataloader.py", line 521, in __next__
    data = self._next_data()
  File "/home/ycarmon/users/maorkehati/anaconda3/envs/optp/lib/python3.9/site-packages/torch/utils/data/dataloader.py", line 1203, in _next_data
    return self._process_data(data)
  File "/home/ycarmon/users/maorkehati/anaconda3/envs/optp/lib/python3.9/site-packages/torch/utils/data/dataloader.py", line 1229, in _process_data
    data.reraise()
  File "/home/ycarmon/users/maorkehati/anaconda3/envs/optp/lib/python3.9/site-packages/torch/_utils.py", line 434, in reraise
    raise exception
RuntimeError: Caught RuntimeError in DataLoader worker process 0.
Original Traceback (most recent call last):
  File "/home/ycarmon/users/maorkehati/anaconda3/envs/optp/lib/python3.9/site-packages/torch/utils/data/_utils/worker.py", line 287, in _worker_loop
    data = fetcher.fetch(index)
  File "/home/ycarmon/users/maorkehati/anaconda3/envs/optp/lib/python3.9/site-packages/torch/utils/data/_utils/fetch.py", line 52, in fetch
    return self.collate_fn(data)
  File "/home/ycarmon/users/maorkehati/anaconda3/envs/optp/lib/python3.9/site-packages/torch/utils/data/_utils/collate.py", line 84, in default_collate
    return [default_collate(samples) for samples in transposed]
  File "/home/ycarmon/users/maorkehati/anaconda3/envs/optp/lib/python3.9/site-packages/torch/utils/data/_utils/collate.py", line 84, in <listcomp>
    return [default_collate(samples) for samples in transposed]
  File "/home/ycarmon/users/maorkehati/anaconda3/envs/optp/lib/python3.9/site-packages/torch/utils/data/_utils/collate.py", line 54, in default_collate
    storage = elem.storage()._new_shared(numel)
  File "/home/ycarmon/users/maorkehati/anaconda3/envs/optp/lib/python3.9/site-packages/torch/storage.py", line 157, in _new_shared
    return cls._new_using_fd(size)
RuntimeError: falseINTERNAL ASSERT FAILED at "../aten/src/ATen/MapAllocator.cpp":263, please report a bug to PyTorch. unable to open shared memory object </torch_40309_14> in read-write mode

